Workbook

Sheet Revenue Analysis
A1: KSA COMPLETE REVENUE ANALYSIS — WHERE EVERY DOLLAR COMES FROM
A2: Source: IRS Form 990 (2011-2024) | EIN: 74-1891991 | 29 member associations | ~23,354 equivalent units
A4: Year | B4: Program Svc Rev (Assessments+Leases) | C4: Investment Income | D4: Other Revenue | E4: Total Revenue | F4: Assessment % of Total | G4: Invest % of Total | H4: YoY Rev Growth | I4: Implied Per Unit Cost | J4: Program Rev YoY Growth | K4: Invest Inc YoY Growth
A5: 2011 | B5: 798934 | C5: 13444 | D5: 7510 | E5: =B5+C5+D5 | F5: =B5/E5 | G5: =C5/E5 | I5: =B5/23354
A6: 2012 | B6: 639431 | C6: 6389 | D6: 16595 | E6: =B6+C6+D6 | F6: =B6/E6 | G6: =C6/E6 | H6: =E6/E5-1 | I6: =B6/23354 | J6: =B6/B5-1 | K6: =IF(C5=0,"N/A",C6/C5-1)
A7: 2013 | B7: 832330 | C7: 4728 | D7: 8320 | E7: =B7+C7+D7 | F7: =B7/E7 | G7: =C7/E7 | H7: =E7/E6-1 | I7: =B7/23354 | J7: =B7/B6-1 | K7: =IF(C6=0,"N/A",C7/C6-1)
A8: 2014 | B8: 748124 | C8: 4563 | D8: 7790 | E8: =B8+C8+D8 | F8: =B8/E8 | G8: =C8/E8 | H8: =E8/E7-1 | I8: =B8/23354 | J8: =B8/B7-1 | K8: =IF(C7=0,"N/A",C8/C7-1)
A9: 2015 | B9: 823714 | C9: 6044 | D9: 8575 | E9: =B9+C9+D9 | F9: =B9/E9 | G9: =C9/E9 | H9: =E9/E8-1 | I9: =B9/23354 | J9: =B9/B8-1 | K9: =IF(C8=0,"N/A",C9/C8-1)
A10: 2016 | B10: 889400 | C10: 9674 | D10: 5490 | E10: =B10+C10+D10 | F10: =B10/E10 | G10: =C10/E10 | H10: =E10/E9-1 | I10: =B10/23354 | J10: =B10/B9-1 | K10: =IF(C9=0,"N/A",C10/C9-1)
A11: 2017 | B11: 873548 | C11: 10486 | D11: 0 | E11: =B11+C11+D11 | F11: =B11/E11 | G11: =C11/E11 | H11: =E11/E10-1 | I11: =B11/23354 | J11: =B11/B10-1 | K11: =IF(C10=0,"N/A",C11/C10-1)
A12: 2018 | B12: 904037 | C12: 22436 | D12: 0 | E12: =B12+C12+D12 | F12: =B12/E12 | G12: =C12/E12 | H12: =E12/E11-1 | I12: =B12/23354 | J12: =B12/B11-1 | K12: =IF(C11=0,"N/A",C12/C11-1)
A13: 2019 | B13: 961787 | C13: 36464 | D13: 0 | E13: =B13+C13+D13 | F13: =B13/E13 | G13: =C13/E13 | H13: =E13/E12-1 | I13: =B13/23354 | J13: =B13/B12-1 | K13: =IF(C12=0,"N/A",C13/C12-1)
A14: 2020 | B14: 1014760 | C14: 16474 | D14: 0 | E14: =B14+C14+D14 | F14: =B14/E14 | G14: =C14/E14 | H14: =E14/E13-1 | I14: =B14/23354 | J14: =B14/B13-1 | K14: =IF(C13=0,"N/A",C14/C13-1)
A15: 2021 | B15: 1024453 | C15: 15504 | D15: 0 | E15: =B15+C15+D15 | F15: =B15/E15 | G15: =C15/E15 | H15: =E15/E14-1 | I15: =B15/23354 | J15: =B15/B14-1 | K15: =IF(C14=0,"N/A",C15/C14-1)
A16: 2022 | B16: 1014641 | C16: 20222 | D16: 0 | E16: =B16+C16+D16 | F16: =B16/E16 | G16: =C16/E16 | H16: =E16/E15-1 | I16: =B16/23354 | J16: =B16/B15-1 | K16: =IF(C15=0,"N/A",C16/C15-1)
A17: 2023 | B17: 991094 | C17: 50707 | D17: 0 | E17: =B17+C17+D17 | F17: =B17/E17 | G17: =C17/E17 | H17: =E17/E16-1 | I17: =B17/23354 | J17: =B17/B16-1 | K17: =IF(C16=0,"N/A",C17/C16-1)
A18: 2024 | B18: 958464 | C18: 90457 | D18: 0 | E18: =B18+C18+D18 | F18: =B18/E18 | G18: =C18/E18 | H18: =E18/E17-1 | I18: =B18/23354 | J18: =B18/B17-1 | K18: =IF(C17=0,"N/A",C18/C17-1)
A20: REVENUE SUMMARY STATISTICS
A21: 14-Year Avg Total Revenue | B21: =AVERAGE(E5:E18)
A22: 14-Year Avg Program Svc Rev | B22: =AVERAGE(B5:B18)
A23: 14-Year Avg Investment Inc | B23: =AVERAGE(C5:C18)
A24: Revenue CAGR (2011→2024) | B24: =(E18/E5)^(1/13)-1
A25: Program Svc CAGR | B25: =(B18/B5)^(1/13)-1
A26: Investment Inc CAGR | B26: =(C18/C5)^(1/13)-1
A27: Avg Per-Unit Assessment | B27: =AVERAGE(I5:I18)
A28: 2024 Per-Unit Assessment | B28: =I18
A29: Revenue Volatility (Std Dev) | B29: =STDEV(E5:E18)
A30: Max Single-Year Revenue | B30: =MAX(E5:E18)
A31: Min Single-Year Revenue | B31: =MIN(E5:E18)
A34: IDENTIFIED REVENUE STREAMS
A35: All revenue flows through TWO lines on the 990:
A37: Revenue Stream | B37: Rate/Basis | C37: Annual Amount | D37: % of Total | E37: Notes
A38: 1. Quarterly Pro-Rata Assessments | B38: ~$41/equivalent unit/year | C38: ~$958K | D38: 91% | E38: Billed to 29 member associations based on equivalent units. Villages pass cost to homeowners within HOA dues.
A39: 2. Field Lease Income (bundled) | B39: Unknown per lease | C39: Bundled in #1 | D39: ?% | E39: 6+ active leases to youth sports orgs. Reports as $0 'net rental income' — likely bundled in program services or at-cost.
A40: 3. Investment Income | B40: 3-4% yield on reserves | C40: ~$90K | D40: 8.6% | E40: Interest/dividends on $2.1M cash reserves. Grew 572% from 2015-2024 as reserves and rates increased.
A41: 4. Other/Misc Revenue | B41: Varies | C41: $0 (recent) | D41: <1% | E41: Was $5-17K/yr (2011-2016), dropped to $0 from 2017. May have been K-sticker fees, pavilion rentals.
A42: 5. KSA Parks Foundation | B42: Tax-deductible donations | C42: <$50K/yr | D42: Separate | E42: Separate 501(c)(3) entity (EIN 27-1433729). Files 990-N. Funds Trees for Kingwood, park donations.
A43: 6. TxDOT Matching Grants | B43: State highway landscaping | C43: $50K (2009) | D43: One-time | E43: Matching funds for entryway landscaping along state right-of-way. Not consistent.
A44: 7. FEMA / Insurance Claims | B44: Post-disaster | C44: Unknown | D44: Irregular | E44: No FEMA income visible on 990s. Harvey recovery costs may have been self-funded from reserves.
A47: KNOWN FIELD LEASE AGREEMENTS
...

Sheet Expense Analysis
A1: KSA EXPENSE ANALYSIS — WHERE EVERY DOLLAR GOES
A2: Budget categories from KSA presentations (2009, 2012). 990 detail locked in scanned PDFs.
A4: Year | B4: Total Expenses | C4: YoY Change | D4: Total Revenue | E4: Net Income | F4: Expense/ Revenue | G4: Per Unit Expense | H4: Expense Volatility
A5: 2011 | B5: 743479 | D5: 819888 | E5: =D5-B5 | F5: =B5/D5 | G5: =B5/23354
A6: 2012 | B6: 724047 | C6: =B6/B5-1 | D6: 662415 | E6: =D6-B6 | F6: =B6/D6 | G6: =B6/23354
A7: 2013 | B7: 911275 | C7: =B7/B6-1 | D7: 845378 | E7: =D7-B7 | F7: =B7/D7 | G7: =B7/23354
A8: 2014 | B8: 649890 | C8: =B8/B7-1 | D8: 760477 | E8: =D8-B8 | F8: =B8/D8 | G8: =B8/23354
A9: 2015 | B9: 771855 | C9: =B9/B8-1 | D9: 838333 | E9: =D9-B9 | F9: =B9/D9 | G9: =B9/23354
A10: 2016 | B10: 789390 | C10: =B10/B9-1 | D10: 904564 | E10: =D10-B10 | F10: =B10/D10 | G10: =B10/23354
A11: 2017 | B11: 895731 | C11: =B11/B10-1 | D11: 884034 | E11: =D11-B11 | F11: =B11/D11 | G11: =B11/23354
A12: 2018 | B12: 745644 | C12: =B12/B11-1 | D12: 926473 | E12: =D12-B12 | F12: =B12/D12 | G12: =B12/23354
A13: 2019 | B13: 850536 | C13: =B13/B12-1 | D13: 998251 | E13: =D13-B13 | F13: =B13/D13 | G13: =B13/23354
A14: 2020 | B14: 1018430 | C14: =B14/B13-1 | D14: 1031234 | E14: =D14-B14 | F14: =B14/D14 | G14: =B14/23354
A15: 2021 | B15: 948240 | C15: =B15/B14-1 | D15: 1039957 | E15: =D15-B15 | F15: =B15/D15 | G15: =B15/23354
A16: 2022 | B16: 861519 | C16: =B16/B15-1 | D16: 1034863 | E16: =D16-B16 | F16: =B16/D16 | G16: =B16/23354
A17: 2023 | B17: 1009164 | C17: =B17/B16-1 | D17: 1041801 | E17: =D17-B17 | F17: =B17/D17 | G17: =B17/23354
A18: 2024 | B18: 1565650 | C18: =B18/B17-1 | D18: 1048921 | E18: =D18-B18 | F18: =B18/D18 | G18: =B18/23354
A20: EXPENSE SUMMARY
A21: 14-Year Avg Expenses | B21: =AVERAGE(B5:B18)
A22: Expense CAGR (2011→2024) | B22: =(B18/B5)^(1/13)-1
A23: Avg Expense/Revenue Ratio | B23: =AVERAGE(F5:F18)
A24: Expense Std Deviation | B24: =STDEV(B5:B18)
A25: Max Single-Year Expense | B25: =MAX(B5:B18)
A26: Min Single-Year Expense | B26: =MIN(B5:B18)
A27: 2024 Per-Unit Expense | B27: =B18/23354
A28: Median Expense (excl 2024) | B28: =MEDIAN(B5:B17)
A29: 2024 vs Median Deviation | B29: =B18/MEDIAN(B5:B17)-1
A32: BUDGET CATEGORY BREAKDOWN (Confirmed from KSA Presentations)
A33: Category | B33: 2009 Amount | C33: 2009 % | D33: 2012 Amount | E33: 2012 % | F33: Growth (2009→2012) | G33: Est. 2024 (at CAGR) | H33: Est. 2024 % | I33: Description
A34: Parks Ops & Maintenance | B34: 336526 | C34: =B34/B39 | D34: 354063 | E34: =D34/D39 | F34: =(D34/B34)^(1/3)-1 | G34: =D34*(1+F34)^12 | H34: =G34/G39 | I34: Landscaping, mowing, repairs, supplies, utilities for 5 parks (356.6 acres)
A35: General & Administrative | B35: 153319 | C35: =B35/B39 | D35: 182783 | E35: =D35/D39 | F35: =(D35/B35)^(1/3)-1 | G35: =D35*(1+F35)^12 | H35: =G35/G39 | I35: KAM management contract, office expenses, umbrella insurance, legal fees, accounting
A36: Entryway Maintenance | B36: 143200 | C36: =B36/B39 | D36: 133772 | E36: =D36/D39 | F36: =(D36/B36)^(1/3)-1 | G36: =D36*(1+F36)^12 | H36: =G36/G39 | I36: Kingwood Dr, North Park Dr, West Lake Houston Pkwy medians + signage
A37: Park Improvements (Capital) | B37: 91100 | C37: =B37/B39 | D37: 118385 | E37: =D37/D39 | F37: =(D37/B37)^(1/3)-1 | G37: =D37*(1+F37)^12 | H37: =G37/G39 | I37: New infrastructure, tee pads, benches, trail improvements, facility upgrades
A38: TxDOT Matching / Public Safety | B38: 67000 | C38: =B38/B39 | D38: 17000 | E38: =D38/D39 | F38: =(D38/B38)^(1/3)-1 | G38: =D38*(1+F38)^12 | H38: =G38/G39 | I38: 2009: $50K TxDOT match + $17K safety. 2012: $17K safety only
A39: TOTAL | B39: =SUM(B34:B38) | C39: =1 | D39: =SUM(D34:D38) | E39: =1 | G39: =SUM(G34:G38)
A41: 2024 EXPENSE ANOMALY ANALYSIS
A42: Actual 2024 Expenses (from 990) | B42: 1565650
A43: Estimated 2024 (from CAGR model) | B43: =G39
A44: Unexplained Excess | B44: =B42-B43
A45: Excess as % of Normal Budget | B45: =B44/B43
...

Sheet DCF Model
A1: 10-YEAR DISCOUNTED CASH FLOW MODEL
A2: Change yellow cells to test scenarios. All green cells are formulas.
A4: MODEL INPUTS
A5: Equivalent Units (2008 census) | B5: 23354 | C5: 1 unit = 1 home. 0.5 = 1 apt. Commercial by sqft.
A6: 2024 Assessment Revenue (actual) | B6: 958464 | C6: From 2024 Form 990 — Program Service Revenue
A7: 2024 Investment Income (actual) | B7: 90457 | C7: From 2024 Form 990
A8: 2024 Total Revenue (actual) | B8: =B6+B7 | C8: =B6+B7 (formula)
A9: 2024 Total Expenses (actual) | B9: 1565650 | C9: Anomalous — 55% above prior year
A10: Normalized Expense Base | B10: 1020000 | C10: Median of 2019-2023 expenses, adjusted for inflation
A11: Starting Cash Reserves | B11: 2092894 | C11: From 2024 balance sheet
A12: Assessment Growth Rate | B12: 0.015 | C12: Historical CAGR ~1.4% (2011-2024); conservative
A13: Expense Growth Rate | B13: 0.035 | C13: Inflation + aging infrastructure. Historical CAGR 5.9% but volatile
A14: Investment Yield on Reserves | B14: 0.04 | C14: 2024 actual: $90K / $2.1M ≈ 4.3%
A15: Discount Rate | B15: 0.05 | C15: Opportunity cost of capital for civic organization
A16: Catastrophe Probability (annual) | B16: 0.067 | C16: 1-in-15 year event (Harvey was 2017, next due ~2032)
A17: Catastrophe Cost | B17: 500000 | C17: Harvey recovery: 2.5 years, est. $500K+ total
A18: Lawsuit Settlement | B18: 500000 | C18: Mills Branch exposure: demands up to $250K, legal fees additional
A19: Lawsuit Year | B19: 2026 | C19: Expected resolution
A20: Lease Income (est, bundled) | B20: 50000 | C20: Estimated — 6 field leases, likely at-cost or nominal
A22: 10-YEAR CASH FLOW PROJECTION
A23: Year | B23: Assessment Revenue | C23: Est. Lease Income | D23: Investment Income | E23: Total Revenue | F23: Operating Expenses | G23: Net Operating Cash Flow | H23: Catastrophe Reserve | I23: Lawsuit Impact | J23: Net Cash Flow | K23: Discount Factor | L23: PV of Cash Flow | M23: Cumulative Cash Reserve | N23: Months of Reserves
A24: 2024 | B24: 958464 | C24: =$B$20 | D24: 90457 | E24: =B24+C24+D24 | F24: 1565650 | G24: =E24-F24 | H24: 0 | I24: 0 | J24: =G24-H24-I24 | K24: 1 | L24: =J24*K24 | M24: 2092894 | N24: =IF(F24=0,0,M24/F24*12)
A25: 2025 | B25: =B24*(1+$B$12) | C25: =$B$20 | D25: =MAX(M24,0)*$B$14 | E25: =B25+C25+D25 | F25: =$B$10*(1+$B$13)^1 | G25: =E25-F25 | H25: =$B$16*$B$17 | I25: =IF(A25=$B$19,$B$18,0) | J25: =G25-H25-I25 | K25: =1/(1+$B$15)^1 | L25: =J25*K25 | M25: =MAX(M24+J25,0) | N25: =IF(F25=0,0,M25/F25*12)
A26: 2026 | B26: =B25*(1+$B$12) | C26: =$B$20 | D26: =MAX(M25,0)*$B$14 | E26: =B26+C26+D26 | F26: =$B$10*(1+$B$13)^2 | G26: =E26-F26 | H26: =$B$16*$B$17 | I26: =IF(A26=$B$19,$B$18,0) | J26: =G26-H26-I26 | K26: =1/(1+$B$15)^2 | L26: =J26*K26 | M26: =MAX(M25+J26,0) | N26: =IF(F26=0,0,M26/F26*12)
A27: 2027 | B27: =B26*(1+$B$12) | C27: =$B$20 | D27: =MAX(M26,0)*$B$14 | E27: =B27+C27+D27 | F27: =$B$10*(1+$B$13)^3 | G27: =E27-F27 | H27: =$B$16*$B$17 | I27: =IF(A27=$B$19,$B$18,0) | J27: =G27-H27-I27 | K27: =1/(1+$B$15)^3 | L27: =J27*K27 | M27: =MAX(M26+J27,0) | N27: =IF(F27=0,0,M27/F27*12)
A28: 2028 | B28: =B27*(1+$B$12) | C28: =$B$20 | D28: =MAX(M27,0)*$B$14 | E28: =B28+C28+D28 | F28: =$B$10*(1+$B$13)^4 | G28: =E28-F28 | H28: =$B$16*$B$17 | I28: =IF(A28=$B$19,$B$18,0) | J28: =G28-H28-I28 | K28: =1/(1+$B$15)^4 | L28: =J28*K28 | M28: =MAX(M27+J28,0) | N28: =IF(F28=0,0,M28/F28*12)
A29: 2029 | B29: =B28*(1+$B$12) | C29: =$B$20 | D29: =MAX(M28,0)*$B$14 | E29: =B29+C29+D29 | F29: =$B$10*(1+$B$13)^5 | G29: =E29-F29 | H29: =$B$16*$B$17 | I29: =IF(A29=$B$19,$B$18,0) | J29: =G29-H29-I29 | K29: =1/(1+$B$15)^5 | L29: =J29*K29 | M29: =MAX(M28+J29,0) | N29: =IF(F29=0,0,M29/F29*12)
A30: 2030 | B30: =B29*(1+$B$12) | C30: =$B$20 | D30: =MAX(M29,0)*$B$14 | E30: =B30+C30+D30 | F30: =$B$10*(1+$B$13)^6 | G30: =E30-F30 | H30: =$B$16*$B$17 | I30: =IF(A30=$B$19,$B$18,0) | J30: =G30-H30-I30 | K30: =1/(1+$B$15)^6 | L30: =J30*K30 | M30: =MAX(M29+J30,0) | N30: =IF(F30=0,0,M30/F30*12)
A31: 2031 | B31: =B30*(1+$B$12) | C31: =$B$20 | D31: =MAX(M30,0)*$B$14 | E31: =B31+C31+D31 | F31: =$B$10*(1+$B$13)^7 | G31: =E31-F31 | H31: =$B$16*$B$17 | I31: =IF(A31=$B$19,$B$18,0) | J31: =G31-H31-I31 | K31: =1/(1+$B$15)^7 | L31: =J31*K31 | M31: =MAX(M30+J31,0) | N31: =IF(F31=0,0,M31/F31*12)
A32: 2032 | B32: =B31*(1+$B$12) | C32: =$B$20 | D32: =MAX(M31,0)*$B$14 | E32: =B32+C32+D32 | F32: =$B$10*(1+$B$13)^8 | G32: =E32-F32 | H32: =$B$16*$B$17 | I32: =IF(A32=$B$19,$B$18,0) | J32: =G32-H32-I32 | K32: =1/(1+$B$15)^8 | L32: =J32*K32 | M32: =MAX(M31+J32,0) | N32: =IF(F32=0,0,M32/F32*12)
A33: 2033 | B33: =B32*(1+$B$12) | C33: =$B$20 | D33: =MAX(M32,0)*$B$14 | E33: =B33+C33+D33 | F33: =$B$10*(1+$B$13)^9 | G33: =E33-F33 | H33: =$B$16*$B$17 | I33: =IF(A33=$B$19,$B$18,0) | J33: =G33-H33-I33 | K33: =1/(1+$B$15)^9 | L33: =J33*K33 | M33: =MAX(M32+J33,0) | N33: =IF(F33=0,0,M33/F33*12)
A34: 2034 | B34: =B33*(1+$B$12) | C34: =$B$20 | D34: =MAX(M33,0)*$B$14 | E34: =B34+C34+D34 | F34: =$B$10*(1+$B$13)^10 | G34: =E34-F34 | H34: =$B$16*$B$17 | I34: =IF(A34=$B$19,$B$18,0) | J34: =G34-H34-I34 | K34: =1/(1+$B$15)^10 | L34: =J34*K34 | M34: =MAX(M33+J34,0) | N34: =IF(F34=0,0,M34/F34*12)
A36: DCF RESULTS — WHAT THE NUMBERS PROVE
A37: NPV of 10-Year Cash Flows | B37: =SUM(L25:L34) | C37: Present value of all future cash flows, discounted at 5%. Negative = organization loses value.
A38: Terminal Cash Reserve (2034) | B38: =M34 | C38: Cash remaining after 10 years. If zero, KSA is insolvent.
A39: Total Undiscounted CF (10yr) | B39: =SUM(J25:J34) | C39: Raw sum of net cash flows before discounting.
A40: Avg Annual Net CF | B40: =AVERAGE(J25:J34) | C40: Average cash burn/gain per year.
A41: Years with Positive CF | B41: =COUNTIF(J25:J34,">"&0) | C41: How many of the 10 years generate surplus.
A42: Years Until Reserves Hit Zero | B42: =COUNTIF(M25:M34,">"&0) | C42: How many years before KSA runs out of cash.
A43: Final Months of Operating Reserve | B43: =N34 | C43: Healthy: 12+. Warning: 6-12. Critical: <6.
...

Sheet Assessment Sensitivity
A1: ASSESSMENT INCREASE SENSITIVITY — PROVING WHAT IT TAKES
A3: INPUTS (from DCF Model sheet)
A4: Current Assessment Rev | B4: ='DCF Model'!B6
A5: Equivalent Units | B5: ='DCF Model'!B5
A6: Current Per-Unit Cost | B6: =B4/B5
A7: Normalized Expenses (Year 1) | B7: ='DCF Model'!B10*(1+'DCF Model'!B13)
A8: Investment Income (est) | B8: ='DCF Model'!B11*'DCF Model'!B14
A9: Lease Income (est) | B9: ='DCF Model'!B20
A10: Year 1 Gap (no change) | B10: =B7-B4-B8-B9
A11: Cash Reserves | B11: ='DCF Model'!B11
A12: Years to Exhaust (at current gap) | B12: =IF(B10<=0,99,B11/B10)
A14: PER-UNIT INCREASE SCENARIOS
A15: Increase Per Unit | B15: New Per-Unit Assessment | C15: % Increase Per Unit | D15: New Total Assessment Rev | E15: Year 1 Total Revenue | F15: Year 1 Expenses | G15: Year 1 Net CF | H15: Years Until Reserves Gone | I15: Sustainable 10 Years? | J15: Monthly Increase/Home
A16: 0 | B16: =$B$6+A16 | C16: =A16/$B$6 | D16: =B16*$B$5 | E16: =D16+$B$8+$B$9 | F16: =$B$7 | G16: =E16-F16 | H16: =IF(G16>=0,99,IF(-G16=0,99,$B$11/(-G16))) | I16: =IF(H16>=10,"YES","NO") | J16: =A16/12
A17: 5 | B17: =$B$6+A17 | C17: =A17/$B$6 | D17: =B17*$B$5 | E17: =D17+$B$8+$B$9 | F17: =$B$7 | G17: =E17-F17 | H17: =IF(G17>=0,99,IF(-G17=0,99,$B$11/(-G17))) | I17: =IF(H17>=10,"YES","NO") | J17: =A17/12
A18: 10 | B18: =$B$6+A18 | C18: =A18/$B$6 | D18: =B18*$B$5 | E18: =D18+$B$8+$B$9 | F18: =$B$7 | G18: =E18-F18 | H18: =IF(G18>=0,99,IF(-G18=0,99,$B$11/(-G18))) | I18: =IF(H18>=10,"YES","NO") | J18: =A18/12
A19: 15 | B19: =$B$6+A19 | C19: =A19/$B$6 | D19: =B19*$B$5 | E19: =D19+$B$8+$B$9 | F19: =$B$7 | G19: =E19-F19 | H19: =IF(G19>=0,99,IF(-G19=0,99,$B$11/(-G19))) | I19: =IF(H19>=10,"YES","NO") | J19: =A19/12
A20: 20 | B20: =$B$6+A20 | C20: =A20/$B$6 | D20: =B20*$B$5 | E20: =D20+$B$8+$B$9 | F20: =$B$7 | G20: =E20-F20 | H20: =IF(G20>=0,99,IF(-G20=0,99,$B$11/(-G20))) | I20: =IF(H20>=10,"YES","NO") | J20: =A20/12
A21: 25 | B21: =$B$6+A21 | C21: =A21/$B$6 | D21: =B21*$B$5 | E21: =D21+$B$8+$B$9 | F21: =$B$7 | G21: =E21-F21 | H21: =IF(G21>=0,99,IF(-G21=0,99,$B$11/(-G21))) | I21: =IF(H21>=10,"YES","NO") | J21: =A21/12
A22: 30 | B22: =$B$6+A22 | C22: =A22/$B$6 | D22: =B22*$B$5 | E22: =D22+$B$8+$B$9 | F22: =$B$7 | G22: =E22-F22 | H22: =IF(G22>=0,99,IF(-G22=0,99,$B$11/(-G22))) | I22: =IF(H22>=10,"YES","NO") | J22: =A22/12
A23: 40 | B23: =$B$6+A23 | C23: =A23/$B$6 | D23: =B23*$B$5 | E23: =D23+$B$8+$B$9 | F23: =$B$7 | G23: =E23-F23 | H23: =IF(G23>=0,99,IF(-G23=0,99,$B$11/(-G23))) | I23: =IF(H23>=10,"YES","NO") | J23: =A23/12
A24: 50 | B24: =$B$6+A24 | C24: =A24/$B$6 | D24: =B24*$B$5 | E24: =D24+$B$8+$B$9 | F24: =$B$7 | G24: =E24-F24 | H24: =IF(G24>=0,99,IF(-G24=0,99,$B$11/(-G24))) | I24: =IF(H24>=10,"YES","NO") | J24: =A24/12
A25: 75 | B25: =$B$6+A25 | C25: =A25/$B$6 | D25: =B25*$B$5 | E25: =D25+$B$8+$B$9 | F25: =$B$7 | G25: =E25-F25 | H25: =IF(G25>=0,99,IF(-G25=0,99,$B$11/(-G25))) | I25: =IF(H25>=10,"YES","NO") | J25: =A25/12
A26: 100 | B26: =$B$6+A26 | C26: =A26/$B$6 | D26: =B26*$B$5 | E26: =D26+$B$8+$B$9 | F26: =$B$7 | G26: =E26-F26 | H26: =IF(G26>=0,99,IF(-G26=0,99,$B$11/(-G26))) | I26: =IF(H26>=10,"YES","NO") | J26: =A26/12
A27: 150 | B27: =$B$6+A27 | C27: =A27/$B$6 | D27: =B27*$B$5 | E27: =D27+$B$8+$B$9 | F27: =$B$7 | G27: =E27-F27 | H27: =IF(G27>=0,99,IF(-G27=0,99,$B$11/(-G27))) | I27: =IF(H27>=10,"YES","NO") | J27: =A27/12
A28: 200 | B28: =$B$6+A28 | C28: =A28/$B$6 | D28: =B28*$B$5 | E28: =D28+$B$8+$B$9 | F28: =$B$7 | G28: =E28-F28 | H28: =IF(G28>=0,99,IF(-G28=0,99,$B$11/(-G28))) | I28: =IF(H28>=10,"YES","NO") | J28: =A28/12
A31: WHAT THIS PROVES
A32: PROOF 1: At $0 increase, KSA runs a structural deficit. Revenue grows slower than expenses (1.5% vs 3.5%).
A33: PROOF 2: The revenue-expense gap COMPOUNDS. Year 1 gap is modest, but by year 5 it accelerates.
A34: PROOF 3: A $5/unit/year increase ($0.42/month per home) generates ~$117K additional revenue — significant.
A35: PROOF 4: Find the row where 'Sustainable 10 Years?' flips from NO to YES — that's the minimum viable increase.
A36: PROOF 5: Even the minimum increase doesn't account for catastrophic events (Harvey) or lawsuits (Mills Branch).
A37: PROOF 6: The 2024 expense spike consumed ~25% of liquid reserves in ONE year. Reserves are finite.
A38: PROOF 7: Assessment revenue per unit (~$41/yr or $3.42/month) is remarkably low for 356 acres of maintained parkland.
A39: PROOF 8: At $200/unit increase, monthly cost per home goes from $3.42 to $20.08 — still low vs comparable HOAs.

Sheet Balance Sheet
A1: KSA BALANCE SHEET ANALYSIS — RESERVE HEALTH
A3: Year | B3: Total Assets | C3: Total Liabilities | D3: Net Assets | E3: Net Asset YoY Change | F3: Debt/Asset Ratio | G3: Net Income (Rev-Exp) | H3: Cash/Invest (est) | I3: Months of Reserves
A4: 2011 | B4: 2987497 | C4: 73750 | D4: 2913747 | F4: =IF(B4=0,0,C4/B4) | G4: =819888-743479 | H4: =B4*0.67 | I4: =IF(743479=0,0,H4/743479*12)
A5: 2012 | B5: 2899789 | C5: 170172 | D5: 2729617 | E5: =D5-D4 | F5: =IF(B5=0,0,C5/B5) | G5: =662415-724047 | H5: =B5*0.67 | I5: =IF(724047=0,0,H5/724047*12)
A6: 2013 | B6: 2674544 | C6: 4640 | D6: 2669904 | E6: =D6-D5 | F6: =IF(B6=0,0,C6/B6) | G6: =845378-911275 | H6: =B6*0.67 | I6: =IF(911275=0,0,H6/911275*12)
A7: 2014 | B7: 2904598 | C7: 124107 | D7: 2780491 | E7: =D7-D6 | F7: =IF(B7=0,0,C7/B7) | G7: =760477-649890 | H7: =B7*0.67 | I7: =IF(649890=0,0,H7/649890*12)
A8: 2015 | B8: 2944439 | C8: 97468 | D8: 2846971 | E8: =D8-D7 | F8: =IF(B8=0,0,C8/B8) | G8: =838333-771855 | H8: =B8*0.67 | I8: =IF(771855=0,0,H8/771855*12)
A9: 2016 | B9: 3045749 | C9: 83604 | D9: 2962145 | E9: =D9-D8 | F9: =IF(B9=0,0,C9/B9) | G9: =904564-789390 | H9: =B9*0.67 | I9: =IF(789390=0,0,H9/789390*12)
A10: 2017 | B10: 3060685 | C10: 110237 | D10: 2950448 | E10: =D10-D9 | F10: =IF(B10=0,0,C10/B10) | G10: =884034-895731 | H10: =B10*0.67 | I10: =IF(895731=0,0,H10/895731*12)
A11: 2018 | B11: 3279346 | C11: 82355 | D11: 3196991 | E11: =D11-D10 | F11: =IF(B11=0,0,C11/B11) | G11: =926473-745644 | H11: =B11*0.67 | I11: =IF(745644=0,0,H11/745644*12)
A12: 2019 | B12: 3344706 | C12: 0 | D12: 3344706 | E12: =D12-D11 | F12: =IF(B12=0,0,C12/B12) | G12: =998251-850536 | H12: =B12*0.67 | I12: =IF(850536=0,0,H12/850536*12)
A13: 2020 | B13: 3357510 | C13: 0 | D13: 3357510 | E13: =D13-D12 | F13: =IF(B13=0,0,C13/B13) | G13: =1031234-1018430 | H13: =B13*0.67 | I13: =IF(1018430=0,0,H13/1018430*12)
A14: 2021 | B14: 3449283 | C14: 56 | D14: 3449227 | E14: =D14-D13 | F14: =IF(B14=0,0,C14/B14) | G14: =1039957-948240 | H14: =B14*0.67 | I14: =IF(948240=0,0,H14/948240*12)
A15: 2022 | B15: 3604403 | C15: 33 | D15: 3604370 | E15: =D15-D14 | F15: =IF(B15=0,0,C15/B15) | G15: =1034863-861519 | H15: =B15*0.67 | I15: =IF(861519=0,0,H15/861519*12)
A16: 2023 | B16: 3644171 | C16: 7164 | D16: 3637007 | E16: =D16-D15 | F16: =IF(B16=0,0,C16/B16) | G16: =1041801-1009164 | H16: =B16*0.67 | I16: =IF(1009164=0,0,H16/1009164*12)
A17: 2024 | B17: 3123778 | C17: 3500 | D17: 3120278 | E17: =D17-D16 | F17: =IF(B17=0,0,C17/B17) | G17: =1048921-1565650 | H17: =B17*0.67 | I17: =IF(1565650=0,0,H17/1565650*12)
A19: RESERVE HEALTH INDICATORS
A20: 2024 Cash/Investments (actual) | B20: 2092894
A21: 2024 Total Expenses | B21: 1565650
A22: Months at 2024 Expense Rate | B22: =B20/B21*12
A23: 2023 Cash/Investments (actual) | B23: 2594104
A24: Cash Decline (2023→2024) | B24: =B23-B20
A25: % of Reserves Lost in 1 Year | B25: =B24/B23
A26: At This Rate, Reserves Last | B26: =IF(B24<=0,99,B20/B24)
A27: Net Assets Peak (2023) | B27: 3637007
A28: Net Assets Now (2024) | B28: 3120278
A29: Decline from Peak | B29: =B27-B28
A30: % Decline from Peak | B30: =B29/B27

Sheet RGDGC Impact
A1: WHAT THIS MEANS FOR RIVER GROVE DISC GOLF CLUB
A3: RIVER GROVE PARK BUDGET ALLOCATION
A4: KSA Total Parks Budget (est 44%) | B4: ='Expense Analysis'!B34 | C4: Parks ops is ~44% of KSA budget (confirmed 2009, 2012)
A5: Number of Parks | B5: 5 | C5: River Grove, East End, Deer Ridge, Northpark, Creekwood
A6: Total Park Acreage | B6: 356.6 | C6: KSA-owned parkland
A7: River Grove Acreage | B7: 74
A8: River Grove % (by acreage) | B8: =B7/B6
A9: Est. River Grove Annual Budget | B9: =B4*B8 | C9: KSA's approximate spend on River Grove
A10: Disc Golf % of River Grove (est) | B10: 0.15 | C10: DG uses ~15% of park area/resources
A11: Est. Annual DG Maintenance | B11: =B9*B10 | C11: What KSA likely spends on disc golf annually
A13: DISC GOLF IMPROVEMENT COSTS & ROI
A14: Improvement | B14: Unit $ | C14: Qty | D14: Total $ | E14: % of RG Budget | F14: Funding Source
A15: Concrete tee pads | B15: 800 | C15: 21 | D15: =B15*C15 | E15: =D15/$B$9 | F15: RGDGC co-fund 50% + KSA Parks Foundation
A16: DGA Mach X baskets | B16: 450 | C16: 21 | D16: =B16*C16 | E16: =D16/$B$9 | F16: Parks Foundation 501(c)(3) donor campaign
A17: Per-hole signage | B17: 150 | C17: 21 | D17: =B17*C17 | E17: =D17/$B$9 | F17: RGDGC member dues
A18: Benches/seating | B18: 300 | C18: 18 | D18: =B18*C18 | E18: =D18/$B$9 | F18: Parks Foundation + memorial dedications
A19: Practice basket area | B19: 2000 | C19: 1 | D19: =B19*C19 | E19: =D19/$B$9 | F19: RGDGC tournament revenue
A20: Drainage improvements | B20: 25000 | C20: 1 | D20: =B20*C20 | E20: =D20/$B$9 | F20: KSA capital budget + HCFCD grant
A21: Trail resurfacing | B21: 8000 | C21: 1 | D21: =B21*C21 | E21: =D21/$B$9 | F21: KSA operating budget
A22: TOTAL ALL IMPROVEMENTS | D22: =SUM(D15:D21) | E22: =D22/$B$9
A24: DISC GOLF VALUE PROPOSITION TO KSA
A25: Estimated weekly players | B25: 150
A26: Annual player visits | B26: =B25*52
A27: Estimated unique annual visitors | B27: =B26*0.3
A28: % Kingwood residents | B28: 0.7
A29: Resident players per year | B29: =B27*B28
A30: KSA cost per player visit | B30: =B11/B26
A31: Cost per unique visitor | B31: =B11/B27
A32: Annual assessment per unit | B32: ='DCF Model'!B6/'DCF Model'!B5
A33: DG cost as % of assessment | B33: =B11/B32

Sheet Forensic Evidence
A1: FORENSIC FINANCIAL EVIDENCE — KSA FRAUD INDICATORS
A2: Analysis from aggressive fraud attorney perspective. All formulas prove claims with 990 data.
A4: EXHIBIT A: RETAINED SURPLUS ANALYSIS
A5: Article VIII requires return of unspent funds. These formulas prove surpluses were retained.
A6: Year | B6: Revenue | C6: Expenses | D6: Surplus (Rev-Exp) | E6: Surplus Returned? | F6: Cumulative Retained | G6: Net Asset Change | H6: Proves Retention?
A7: 2011 | B7: 819888 | C7: 743479 | D7: =B7-C7 | E7: UNKNOWN | F7: =SUMPRODUCT((D$7:D7)*(D$7:D7>0)) | G7: 0 | H7: N/A
A8: 2012 | B8: 662415 | C8: 724047 | D8: =B8-C8 | E8: UNKNOWN | F8: =SUMPRODUCT((D$7:D8)*(D$7:D8>0)) | G8: =2729617-2913747 | H8: =IF(AND(D8>0,G8>0),"YES - RETAINED","Inconclusive")
A9: 2013 | B9: 845378 | C9: 911275 | D9: =B9-C9 | E9: UNKNOWN | F9: =SUMPRODUCT((D$7:D9)*(D$7:D9>0)) | G9: =2669904-2729617 | H9: =IF(AND(D9>0,G9>0),"YES - RETAINED","Inconclusive")
A10: 2014 | B10: 760477 | C10: 649890 | D10: =B10-C10 | E10: UNKNOWN | F10: =SUMPRODUCT((D$7:D10)*(D$7:D10>0)) | G10: =2780491-2669904 | H10: =IF(AND(D10>0,G10>0),"YES - RETAINED","Inconclusive")
A11: 2015 | B11: 838333 | C11: 771855 | D11: =B11-C11 | E11: UNKNOWN | F11: =SUMPRODUCT((D$7:D11)*(D$7:D11>0)) | G11: =2846971-2780491 | H11: =IF(AND(D11>0,G11>0),"YES - RETAINED","Inconclusive")
A12: 2016 | B12: 904564 | C12: 789390 | D12: =B12-C12 | E12: UNKNOWN | F12: =SUMPRODUCT((D$7:D12)*(D$7:D12>0)) | G12: =2962145-2846971 | H12: =IF(AND(D12>0,G12>0),"YES - RETAINED","Inconclusive")
A13: 2017 | B13: 884034 | C13: 895731 | D13: =B13-C13 | E13: UNKNOWN | F13: =SUMPRODUCT((D$7:D13)*(D$7:D13>0)) | G13: =2950448-2962145 | H13: =IF(AND(D13>0,G13>0),"YES - RETAINED","Inconclusive")
A14: 2018 | B14: 926473 | C14: 745644 | D14: =B14-C14 | E14: UNKNOWN | F14: =SUMPRODUCT((D$7:D14)*(D$7:D14>0)) | G14: =3196991-2950448 | H14: =IF(AND(D14>0,G14>0),"YES - RETAINED","Inconclusive")
A15: 2019 | B15: 998251 | C15: 850536 | D15: =B15-C15 | E15: UNKNOWN | F15: =SUMPRODUCT((D$7:D15)*(D$7:D15>0)) | G15: =3344706-3196991 | H15: =IF(AND(D15>0,G15>0),"YES - RETAINED","Inconclusive")
A16: 2020 | B16: 1031234 | C16: 1018430 | D16: =B16-C16 | E16: UNKNOWN | F16: =SUMPRODUCT((D$7:D16)*(D$7:D16>0)) | G16: =3357510-3344706 | H16: =IF(AND(D16>0,G16>0),"YES - RETAINED","Inconclusive")
A17: 2021 | B17: 1039957 | C17: 948240 | D17: =B17-C17 | E17: UNKNOWN | F17: =SUMPRODUCT((D$7:D17)*(D$7:D17>0)) | G17: =3449227-3357510 | H17: =IF(AND(D17>0,G17>0),"YES - RETAINED","Inconclusive")
A18: 2022 | B18: 1034863 | C18: 861519 | D18: =B18-C18 | E18: UNKNOWN | F18: =SUMPRODUCT((D$7:D18)*(D$7:D18>0)) | G18: =3604370-3449227 | H18: =IF(AND(D18>0,G18>0),"YES - RETAINED","Inconclusive")
A19: 2023 | B19: 1041801 | C19: 1009164 | D19: =B19-C19 | E19: UNKNOWN | F19: =SUMPRODUCT((D$7:D19)*(D$7:D19>0)) | G19: =3637007-3604370 | H19: =IF(AND(D19>0,G19>0),"YES - RETAINED","Inconclusive")
A20: 2024 | B20: 1048921 | C20: 1565650 | D20: =B20-C20 | E20: UNKNOWN | F20: =SUMPRODUCT((D$7:D20)*(D$7:D20>0)) | G20: =3120278-3637007 | H20: =IF(AND(D20>0,G20>0),"YES - RETAINED","Inconclusive")
A22: EXHIBIT A FINDINGS
A23: Total Years with Surplus | B23: =COUNTIF(D7:D20,">"&0)
A24: Total Surplus Generated (all years) | B24: =SUMPRODUCT((D7:D20)*(D7:D20>0))
A25: Total Deficit Years | B25: =COUNTIF(D7:D20,"<"&0)
A26: Total Deficits | B26: =SUMPRODUCT((D7:D20)*(D7:D20<0))
A27: Net Surplus Over 14 Years | B27: =SUM(D7:D20)
A28: Years Where Surplus Was Provably Retained | B28: =COUNTIF(H7:H20,"YES*")
A29: Net Asset Growth (2011→2024) | B29: =3120278-2913747
A30: If All Surpluses Returned: Expected Net Asset Change | B30: =B26
A31: Actual Net Asset Change | B31: =B29
A32: DISCREPANCY (Surplus Retained) | B32: =B29-B30
A35: EXHIBIT B: UNDISCLOSED KAM COMPENSATION
A36: KSA Reports Officer Compensation | B36: 0 | C36: Form 990 Part VII: $0 for all officers including McCormick
A37: KSA Reports Employee Count | B37: 0 | C37: Form 990: 0 employees, all years
A38: G&A Budget (2012 actual) | B38: 182783 | C38: Includes KAM management contract (amount undisclosed)
A39: G&A Budget (2009 actual) | B39: 153319 | C39: KAM contract embedded here
A40: G&A CAGR (2009→2012) | B40: =(B38/B39)^(1/3)-1 | C40: formula
A41: Estimated 2024 G&A (at CAGR) | B41: =B38*(1+B40)^12 | C41: formula
A42: KAM Contract Estimate (50-70% of G&A) | B42: =B41*0.5 | C42: Industry standard: management = 50-70% of G&A
A43: KAM Contract Estimate (HIGH) | B43: =B41*0.7 | C43: 70% of estimated G&A
A44: Additional: KAM collects from village HOAs | B44: UNDISCLOSED | C44: KAM manages both KSA and individual villages
...
